Traceback (most recent call last):
  File "/usr/share/miniconda3/envs/obsastro/lib/python3.8/site-packages/jupyter_cache/executors/utils.py", line 58, in single_nb_execution
    executenb(
  File "/usr/share/miniconda3/envs/obsastro/lib/python3.8/site-packages/nbclient/client.py", line 1305, in execute
    return NotebookClient(nb=nb, resources=resources, km=km, **kwargs).execute()
  File "/usr/share/miniconda3/envs/obsastro/lib/python3.8/site-packages/jupyter_core/utils/__init__.py", line 173, in wrapped
    return loop.run_until_complete(inner)
  File "/usr/share/miniconda3/envs/obsastro/lib/python3.8/asyncio/base_events.py", line 616, in run_until_complete
    return future.result()
  File "/usr/share/miniconda3/envs/obsastro/lib/python3.8/site-packages/nbclient/client.py", line 705, in async_execute
    await self.async_execute_cell(
  File "/usr/share/miniconda3/envs/obsastro/lib/python3.8/site-packages/nbclient/client.py", line 1058, in async_execute_cell
    await self._check_raise_for_error(cell, cell_index, exec_reply)
  File "/usr/share/miniconda3/envs/obsastro/lib/python3.8/site-packages/nbclient/client.py", line 914, in _check_raise_for_error
    raise CellExecutionError.from_cell_and_msg(cell, exec_reply_content)
nbclient.exceptions.CellExecutionError: An error occurred while executing the following cell:
------------------
import os
from astropy.io import fits
from utils import show_image

path = '/Users/jiaxuanl/Dropbox (Princeton)/Data/IFU-M/Mar22/'
os.chdir(path)
------------------


[0;31m---------------------------------------------------------------------------[0m
[0;31mModuleNotFoundError[0m                       Traceback (most recent call last)
Cell [0;32mIn[2], line 3[0m
[1;32m      1[0m [38;5;28;01mimport[39;00m [38;5;21;01mos[39;00m
[1;32m      2[0m [38;5;28;01mfrom[39;00m [38;5;21;01mastropy[39;00m[38;5;21;01m.[39;00m[38;5;21;01mio[39;00m [38;5;28;01mimport[39;00m fits
[0;32m----> 3[0m [38;5;28;01mfrom[39;00m [38;5;21;01mutils[39;00m [38;5;28;01mimport[39;00m show_image
[1;32m      5[0m path [38;5;241m=[39m [38;5;124m'[39m[38;5;124m/Users/jiaxuanl/Dropbox (Princeton)/Data/IFU-M/Mar22/[39m[38;5;124m'[39m
[1;32m      6[0m os[38;5;241m.[39mchdir(path)

[0;31mModuleNotFoundError[0m: No module named 'utils'

